Workbook

Sheet SKU_Base
A1: Статус | B1: Код товару | C1: Назва товару | D1: Категорія | E1: Од. (ориг) | F1: Інвойсна ціна (USD) | G1: Код митниці | H1: Імпортний коеф. | I1: Собівар- тість (грн) | J1: Маржа кл. D1 % | K1: Маржа факт. чиста D1 | L1: Маржа факт. чиста D2 | M1: Маржа факт. чиста D3 | N1: Маржа факт. чиста D4 Buy | O1: Маржа факт. чиста D4 Drop | P1: Маржа факт. чиста D5 | Q1: Маржа факт. чиста D6 | R1: RRP розрах. (грн, D1) | S1: RRP базова (корегування) | T1: RRP ефективна | U1: Роль SKU | V1: Ринок мін. (грн) | W1: Ринок макс. (грн) | X1: Відповідність ринку | Y1: Примітки | AU1: Дата оновлення | AV1: Наценка D4 НІ
B2: B7821 | C2: RAVER BAT. LITHIUM 1.5V,AA | D2: Батарейки | E2: 2 | F2: 1.589 | G2: 8506501000 | H2: 1.35 | I2: =IFERROR(F2*Settings!$B$2*H2*IF(AND(ISNUMBER(E2),E2>1),E2,1),"") | J2: =Settings!$B$66 | K2: =IFERROR(IF(T2="","",(T2*(1-AN2)*(1-Settings!$B$17)-I2)/(T2*(1-AN2)*(1-Settings!$B$17))),"") | L2: =IFERROR(IF(T2="","",(T2*(1-AO2)*(1-Settings!$C$17)-I2)/(T2*(1-AO2)*(1-Settings!$C$17))),"") | M2: =IFERROR(IF(T2="","",(T2*(1-AP2)*(1-Settings!$D$17)-I2)/(T2*(1-AP2)*(1-Settings!$D$17))),"") | N2: =IFERROR(IF(T2="","",(T2*(1-AQ2)*(1-Settings!$F$17)-I2)/(T2*(1-AQ2)*(1-Settings!$F$17))),"") | O2: =IFERROR(IF(T2="","",(T2*(1-AR2)*(1-Settings!$G$17)-I2)/(T2*(1-AR2)*(1-Settings!$G$17))),"") | P2: =IFERROR(IF(T2="","",(T2*(1-AS2)*(1-Settings!$H$17)-I2)/(T2*(1-AS2)*(1-Settings!$H$17))),"") | Q2: =IFERROR(IF(T2="","",(T2*(1-AT2)*(1-Settings!$I$68)*(1-Settings!$I$17)-I2)/(T2*(1-AT2)*(1-Settings!$I$68)*(1-Settings!$I$17))),"") | R2: =IFERROR(IF(OR(I2="",Z2>=1,Settings!$B$17>=1,AN2>=1),"",IF(MOD(ROUND(I2/(1-Z2)/(1-Settings!$B$17)/(1-AN2),0),10)=0,ROUND(I2/(1-Z2)/(1-Settings!$B$17)/(1-AN2),0)-1,IF(MOD(ROUND(I2/(1-Z2)/(1-Settings!$B$17)/(1-AN2),0),10)<=5,FLOOR(ROUND(I2/(1-Z2)/(1-Settings!$B$17)/(1-AN2),0),10)+6,FLOOR(ROUND(I2/(1-Z2)/(1-Settings!$B$17)/(1-AN2),0),10)+9))),"") | S2: 360 | T2: =IF(S2<>"", IF(MOD(S2,10)=0,S2-1,IF(MOD(S2,10)<=5,FLOOR(S2,10)+6,FLOOR(S2,10)+9)), R2) | U2: Маржинальний | X2: =IFERROR(IF(OR(V2="",W2="",T2=""),"", IF(T2>W2,"Дорогий",IF(T2<V2,"Дешевий","У ринку"))),"") | Z2: =CHOOSE(MATCH(IF($U2="","Основний",$U2),{"Трафіковий","Основний","Маржинальний","Сезонний","Стратегічний"},0),0.16,0.19,0.24,0.23,0.28) | AA2: =CHOOSE(MATCH(IF($U2="","Основний",$U2),{"Трафіковий","Основний","Маржинальний","Сезонний","Стратегічний"},0),0.18,0.21,0.26,0.25,0.3) | AB2: =CHOOSE(MATCH(IF($U2="","Основний",$U2),{"Трафіковий","Основний","Маржинальний","Сезонний","Стратегічний"},0),0.19,0.22,0.28,0.26,0.32) | AC2: =CHOOSE(MATCH(IF($U2="","Основний",$U2),{"Трафіковий","Основний","Маржинальний","Сезонний","Стратегічний"},0),0.17,0.2,0.25,0.24,0.28) | AD2: =CHOOSE(MATCH(IF($U2="","Основний",$U2),{"Трафіковий","Основний","Маржинальний","Сезонний","Стратегічний"},0),0.18,0.21,0.26,0.25,0.3) | AE2: =CHOOSE(MATCH(IF($U2="","Основний",$U2),{"Трафіковий","Основний","Маржинальний","Сезонний","Стратегічний"},0),0.18,0.2,0.28,0.27,0.32) | AF2: =CHOOSE(MATCH(IF($U2="","Основний",$U2),{"Трафіковий","Основний","Маржинальний","Сезонний","Стратегічний"},0),0.15,0.175,0.22,0.21,0.25) | AG2: =CHOOSE(MATCH(IF($U2="","Основний",$U2),{"Трафіковий","Основний","Маржинальний","Сезонний","Стратегічний"},0),0.13,0.16,0.21,0.2,0.25) | AH2: =CHOOSE(MATCH(IF($U2="","Основний",$U2),{"Трафіковий","Основний","Маржинальний","Сезонний","Стратегічний"},0),0.15,0.18,0.23,0.22,0.27) | AI2: =CHOOSE(MATCH(IF($U2="","Основний",$U2),{"Трафіковий","Основний","Маржинальний","Сезонний","Стратегічний"},0),0.16,0.19,0.25,0.23,0.29) | AJ2: =CHOOSE(MATCH(IF($U2="","Основний",$U2),{"Трафіковий","Основний","Маржинальний","Сезонний","Стратегічний"},0),0.14,0.17,0.22,0.21,0.25) | AK2: =CHOOSE(MATCH(IF($U2="","Основний",$U2),{"Трафіковий","Основний","Маржинальний","Сезонний","Стратегічний"},0),0.15,0.18,0.23,0.22,0.27) | AL2: =CHOOSE(MATCH(IF($U2="","Основний",$U2),{"Трафіковий","Основний","Маржинальний","Сезонний","Стратегічний"},0),0.15,0.17,0.25,0.24,0.29) | AM2: =CHOOSE(MATCH(IF($U2="","Основний",$U2),{"Трафіковий","Основний","Маржинальний","Сезонний","Стратегічний"},0),0.12,0.145,0.19,0.18,0.22) | AN2: =CHOOSE(MATCH(IF($U2="","Основний",$U2),{"Трафіковий","Основний","Маржинальний","Сезонний","Стратегічний"},0),Settings!$B$78,Settings!$B$80,Settings!$B$82,Settings!$B$84,Settings!$B$86) | AO2: =CHOOSE(MATCH(IF($U2="","Основний",$U2),{"Трафіковий","Основний","Маржинальний","Сезонний","Стратегічний"},0),Settings!$C$78,Settings!$C$80,Settings!$C$82,Settings!$C$84,Settings!$C$86) | AP2: =CHOOSE(MATCH(IF($U2="","Основний",$U2),{"Трафіковий","Основний","Маржинальний","Сезонний","Стратегічний"},0),Settings!$D$78,Settings!$D$80,Settings!$D$82,Settings!$D$84,Settings!$D$86) | AQ2: =CHOOSE(MATCH(IF($U2="","Основний",$U2),{"Трафіковий","Основний","Маржинальний","Сезонний","Стратегічний"},0),Settings!$F$78,Settings!$F$80,Settings!$F$82,Settings!$F$84,Settings!$F$86) | AR2: =CHOOSE(MATCH(IF($U2="","Основний",$U2),{"Трафіковий","Основний","Маржинальний","Сезонний","Стратегічний"},0),Settings!$G$78,Settings!$G$80,Settings!$G$82,Settings!$G$84,Settings!$G$86) | AS2: =CHOOSE(MATCH(IF($U2="","Основний",$U2),{"Трафіковий","Основний","Маржинальний","Сезонний","Стратегічний"},0),Settings!$H$78,Settings!$H$80,Settings!$H$82,Settings!$H$84,Settings!$H$86) | AT2: =CHOOSE(MATCH(IF($U2="","Основний",$U2),{"Трафіковий","Основний","Маржинальний","Сезонний","Стратегічний"},0),Settings!$I$78,Settings!$I$80,Settings!$I$82,Settings!$I$84,Settings!$I$86) | AV2: 1.4
B3: B7811 | C3: RAVER BAT. LITHIUM 1.5V,AAA | D3: Батарейки | E3: 2 | F3: 1.241 | G3: 8506501000 | H3: 1.35 | I3: =IFERROR(F3*Settings!$B$2*H3*IF(AND(ISNUMBER(E3),E3>1),E3,1),"") | J3: =Settings!$B$66 | K3: =IFERROR(IF(T3="","",(T3*(1-AN3)*(1-Settings!$B$17)-I3)/(T3*(1-AN3)*(1-Settings!$B$17))),"") | L3: =IFERROR(IF(T3="","",(T3*(1-AO3)*(1-Settings!$C$17)-I3)/(T3*(1-AO3)*(1-Settings!$C$17))),"") | M3: =IFERROR(IF(T3="","",(T3*(1-AP3)*(1-Settings!$D$17)-I3)/(T3*(1-AP3)*(1-Settings!$D$17))),"") | N3: =IFERROR(IF(T3="","",(T3*(1-AQ3)*(1-Settings!$F$17)-I3)/(T3*(1-AQ3)*(1-Settings!$F$17))),"") | O3: =IFERROR(IF(T3="","",(T3*(1-AR3)*(1-Settings!$G$17)-I3)/(T3*(1-AR3)*(1-Settings!$G$17))),"") | P3: =IFERROR(IF(T3="","",(T3*(1-AS3)*(1-Settings!$H$17)-I3)/(T3*(1-AS3)*(1-Settings!$H$17))),"") | Q3: =IFERROR(IF(T3="","",(T3*(1-AT3)*(1-Settings!$I$68)*(1-Settings!$I$17)-I3)/(T3*(1-AT3)*(1-Settings!$I$68)*(1-Settings!$I$17))),"") | R3: =IFERROR(IF(OR(I3="",Z3>=1,Settings!$B$17>=1,AN3>=1),"",IF(MOD(ROUND(I3/(1-Z3)/(1-Settings!$B$17)/(1-AN3),0),10)=0,ROUND(I3/(1-Z3)/(1-Settings!$B$17)/(1-AN3),0)-1,IF(MOD(ROUND(I3/(1-Z3)/(1-Settings!$B$17)/(1-AN3),0),10)<=5,FLOOR(ROUND(I3/(1-Z3)/(1-Settings!$B$17)/(1-AN3),0),10)+6,FLOOR(ROUND(I3/(1-Z3)/(1-Settings!$B$17)/(1-AN3),0),10)+9))),"") | S3: 289 | T3: =IF(S3<>"", IF(MOD(S3,10)=0,S3-1,IF(MOD(S3,10)<=5,FLOOR(S3,10)+6,FLOOR(S3,10)+9)), R3) | U3: Маржинальний | X3: =IFERROR(IF(OR(V3="",W3="",T3=""),"", IF(T3>W3,"Дорогий",IF(T3<V3,"Дешевий","У ринку"))),"") | Z3: =CHOOSE(MATCH(IF($U3="","Основний",$U3),{"Трафіковий","Основний","Маржинальний","Сезонний","Стратегічний"},0),0.16,0.19,0.24,0.23,0.28) | AA3: =CHOOSE(MATCH(IF($U3="","Основний",$U3),{"Трафіковий","Основний","Маржинальний","Сезонний","Стратегічний"},0),0.18,0.21,0.26,0.25,0.3) | AB3: =CHOOSE(MATCH(IF($U3="","Основний",$U3),{"Трафіковий","Основний","Маржинальний","Сезонний","Стратегічний"},0),0.19,0.22,0.28,0.26,0.32) | AC3: =CHOOSE(MATCH(IF($U3="","Основний",$U3),{"Трафіковий","Основний","Маржинальний","Сезонний","Стратегічний"},0),0.17,0.2,0.25,0.24,0.28) | AD3: =CHOOSE(MATCH(IF($U3="","Основний",$U3),{"Трафіковий","Основний","Маржинальний","Сезонний","Стратегічний"},0),0.18,0.21,0.26,0.25,0.3) | AE3: =CHOOSE(MATCH(IF($U3="","Основний",$U3),{"Трафіковий","Основний","Маржинальний","Сезонний","Стратегічний"},0),0.18,0.2,0.28,0.27,0.32) | AF3: =CHOOSE(MATCH(IF($U3="","Основний",$U3),{"Трафіковий","Основний","Маржинальний","Сезонний","Стратегічний"},0),0.15,0.175,0.22,0.21,0.25) | AG3: =CHOOSE(MATCH(IF($U3="","Основний",$U3),{"Трафіковий","Основний","Маржинальний","Сезонний","Стратегічний"},0),0.13,0.16,0.21,0.2,0.25) | AH3: =CHOOSE(MATCH(IF($U3="","Основний",$U3),{"Трафіковий","Основний","Маржинальний","Сезонний","Стратегічний"},0),0.15,0.18,0.23,0.22,0.27) | AI3: =CHOOSE(MATCH(IF($U3="","Основний",$U3),{"Трафіковий","Основний","Маржинальний","Сезонний","Стратегічний"},0),0.16,0.19,0.25,0.23,0.29) | AJ3: =CHOOSE(MATCH(IF($U3="","Основний",$U3),{"Трафіковий","Основний","Маржинальний","Сезонний","Стратегічний"},0),0.14,0.17,0.22,0.21,0.25) | AK3: =CHOOSE(MATCH(IF($U3="","Основний",$U3),{"Трафіковий","Основний","Маржинальний","Сезонний","Стратегічний"},0),0.15,0.18,0.23,0.22,0.27) | AL3: =CHOOSE(MATCH(IF($U3="","Основний",$U3),{"Трафіковий","Основний","Маржинальний","Сезонний","Стратегічний"},0),0.15,0.17,0.25,0.24,0.29) | AM3: =CHOOSE(MATCH(IF($U3="","Основний",$U3),{"Трафіковий","Основний","Маржинальний","Сезонний","Стратегічний"},0),0.12,0.145,0.19,0.18,0.22) | AN3: =CHOOSE(MATCH(IF($U3="","Основний",$U3),{"Трафіковий","Основний","Маржинальний","Сезонний","Стратегічний"},0),Settings!$B$78,Settings!$B$80,Settings!$B$82,Settings!$B$84,Settings!$B$86) | AO3: =CHOOSE(MATCH(IF($U3="","Основний",$U3),{"Трафіковий","Основний","Маржинальний","Сезонний","Стратегічний"},0),Settings!$C$78,Settings!$C$80,Settings!$C$82,Settings!$C$84,Settings!$C$86) | AP3: =CHOOSE(MATCH(IF($U3="","Основний",$U3),{"Трафіковий","Основний","Маржинальний","Сезонний","Стратегічний"},0),Settings!$D$78,Settings!$D$80,Settings!$D$82,Settings!$D$84,Settings!$D$86) | AQ3: =CHOOSE(MATCH(IF($U3="","Основний",$U3),{"Трафіковий","Основний","Маржинальний","Сезонний","Стратегічний"},0),Settings!$F$78,Settings!$F$80,Settings!$F$82,Settings!$F$84,Settings!$F$86) | AR3: =CHOOSE(MATCH(IF($U3="","Основний",$U3),{"Трафіковий","Основний","Маржинальний","Сезонний","Стратегічний"},0),Settings!$G$78,Settings!$G$80,Settings!$G$82,Settings!$G$84,Settings!$G$86) | AS3: =CHOOSE(MATCH(IF($U3="","Основний",$U3),{"Трафіковий","Основний","Маржинальний","Сезонний","Стратегічний"},0),Settings!$H$78,Settings!$H$80,Settings!$H$82,Settings!$H$84,Settings!$H$86) | AT3: =CHOOSE(MATCH(IF($U3="","Основний",$U3),{"Трафіковий","Основний","Маржинальний","Сезонний","Стратегічний"},0),Settings!$I$78,Settings!$I$80,Settings!$I$82,Settings!$I$84,Settings!$I$86) | AV3: 1.4
B4: B7911 | C4: RAVER BAT.ALKALINE LR03 4BL | D4: Батарейки | E4: 4 | F4: 0.134 | G4: 8506101100 | H4: 1.35 | I4: =IFERROR(F4*Settings!$B$2*H4*IF(AND(ISNUMBER(E4),E4>1),E4,1),"") | J4: =Settings!$B$66 | K4: =IFERROR(IF(T4="","",(T4*(1-AN4)*(1-Settings!$B$17)-I4)/(T4*(1-AN4)*(1-Settings!$B$17))),"") | L4: =IFERROR(IF(T4="","",(T4*(1-AO4)*(1-Settings!$C$17)-I4)/(T4*(1-AO4)*(1-Settings!$C$17))),"") | M4: =IFERROR(IF(T4="","",(T4*(1-AP4)*(1-Settings!$D$17)-I4)/(T4*(1-AP4)*(1-Settings!$D$17))),"") | N4: =IFERROR(IF(T4="","",(T4*(1-AQ4)*(1-Settings!$F$17)-I4)/(T4*(1-AQ4)*(1-Settings!$F$17))),"") | O4: =IFERROR(IF(T4="","",(T4*(1-AR4)*(1-Settings!$G$17)-I4)/(T4*(1-AR4)*(1-Settings!$G$17))),"") | P4: =IFERROR(IF(T4="","",(T4*(1-AS4)*(1-Settings!$H$17)-I4)/(T4*(1-AS4)*(1-Settings!$H$17))),"") | Q4: =IFERROR(IF(T4="","",(T4*(1-AT4)*(1-Settings!$I$68)*(1-Settings!$I$17)-I4)/(T4*(1-AT4)*(1-Settings!$I$68)*(1-Settings!$I$17))),"") | R4: =IFERROR(IF(OR(I4="",Z4>=1,Settings!$B$17>=1,AN4>=1),"",IF(MOD(ROUND(I4/(1-Z4)/(1-Settings!$B$17)/(1-AN4),0),10)=0,ROUND(I4/(1-Z4)/(1-Settings!$B$17)/(1-AN4),0)-1,IF(MOD(ROUND(I4/(1-Z4)/(1-Settings!$B$17)/(1-AN4),0),10)<=5,FLOOR(ROUND(I4/(1-Z4)/(1-Settings!$B$17)/(1-AN4),0),10)+6,FLOOR(ROUND(I4/(1-Z4)/(1-Settings!$B$17)/(1-AN4),0),10)+9))),"") | S4: 89 | T4: =IF(S4<>"", IF(MOD(S4,10)=0,S4-1,IF(MOD(S4,10)<=5,FLOOR(S4,10)+6,FLOOR(S4,10)+9)), R4) | U4: Трафіковий | X4: =IFERROR(IF(OR(V4="",W4="",T4=""),"", IF(T4>W4,"Дорогий",IF(T4<V4,"Дешевий","У ринку"))),"") | Z4: =CHOOSE(MATCH(IF($U4="","Основний",$U4),{"Трафіковий","Основний","Маржинальний","Сезонний","Стратегічний"},0),0.16,0.19,0.24,0.23,0.28) | AA4: =CHOOSE(MATCH(IF($U4="","Основний",$U4),{"Трафіковий","Основний","Маржинальний","Сезонний","Стратегічний"},0),0.18,0.21,0.26,0.25,0.3) | AB4: =CHOOSE(MATCH(IF($U4="","Основний",$U4),{"Трафіковий","Основний","Маржинальний","Сезонний","Стратегічний"},0),0.19,0.22,0.28,0.26,0.32) | AC4: =CHOOSE(MATCH(IF($U4="","Основний",$U4),{"Трафіковий","Основний","Маржинальний","Сезонний","Стратегічний"},0),0.17,0.2,0.25,0.24,0.28) | AD4: =CHOOSE(MATCH(IF($U4="","Основний",$U4),{"Трафіковий","Основний","Маржинальний","Сезонний","Стратегічний"},0),0.18,0.21,0.26,0.25,0.3) | AE4: =CHOOSE(MATCH(IF($U4="","Основний",$U4),{"Трафіковий","Основний","Маржинальний","Сезонний","Стратегічний"},0),0.18,0.2,0.28,0.27,0.32) | AF4: =CHOOSE(MATCH(IF($U4="","Основний",$U4),{"Трафіковий","Основний","Маржинальний","Сезонний","Стратегічний"},0),0.15,0.175,0.22,0.21,0.25) | AG4: =CHOOSE(MATCH(IF($U4="","Основний",$U4),{"Трафіковий","Основний","Маржинальний","Сезонний","Стратегічний"},0),0.13,0.16,0.21,0.2,0.25) | AH4: =CHOOSE(MATCH(IF($U4="","Основний",$U4),{"Трафіковий","Основний","Маржинальний","Сезонний","Стратегічний"},0),0.15,0.18,0.23,0.22,0.27) | AI4: =CHOOSE(MATCH(IF($U4="","Основний",$U4),{"Трафіковий","Основний","Маржинальний","Сезонний","Стратегічний"},0),0.16,0.19,0.25,0.23,0.29) | AJ4: =CHOOSE(MATCH(IF($U4="","Основний",$U4),{"Трафіковий","Основний","Маржинальний","Сезонний","Стратегічний"},0),0.14,0.17,0.22,0.21,0.25) | AK4: =CHOOSE(MATCH(IF($U4="","Основний",$U4),{"Трафіковий","Основний","Маржинальний","Сезонний","Стратегічний"},0),0.15,0.18,0.23,0.22,0.27) | AL4: =CHOOSE(MATCH(IF($U4="","Основний",$U4),{"Трафіковий","Основний","Маржинальний","Сезонний","Стратегічний"},0),0.15,0.17,0.25,0.24,0.29) | AM4: =CHOOSE(MATCH(IF($U4="","Основний",$U4),{"Трафіковий","Основний","Маржинальний","Сезонний","Стратегічний"},0),0.12,0.145,0.19,0.18,0.22) | AN4: =CHOOSE(MATCH(IF($U4="","Основний",$U4),{"Трафіковий","Основний","Маржинальний","Сезонний","Стратегічний"},0),Settings!$B$78,Settings!$B$80,Settings!$B$82,Settings!$B$84,Settings!$B$86) | AO4: =CHOOSE(MATCH(IF($U4="","Основний",$U4),{"Трафіковий","Основний","Маржинальний","Сезонний","Стратегічний"},0),Settings!$C$78,Settings!$C$80,Settings!$C$82,Settings!$C$84,Settings!$C$86) | AP4: =CHOOSE(MATCH(IF($U4="","Основний",$U4),{"Трафіковий","Основний","Маржинальний","Сезонний","Стратегічний"},0),Settings!$D$78,Settings!$D$80,Settings!$D$82,Settings!$D$84,Settings!$D$86) | AQ4: =CHOOSE(MATCH(IF($U4="","Основний",$U4),{"Трафіковий","Основний","Маржинальний","Сезонний","Стратегічний"},0),Settings!$F$78,Settings!$F$80,Settings!$F$82,Settings!$F$84,Settings!$F$86) | AR4: =CHOOSE(MATCH(IF($U4="","Основний",$U4),{"Трафіковий","Основний","Маржинальний","Сезонний","Стратегічний"},0),Settings!$G$78,Settings!$G$80,Settings!$G$82,Settings!$G$84,Settings!$G$86) | AS4: =CHOOSE(MATCH(IF($U4="","Основний",$U4),{"Трафіковий","Основний","Маржинальний","Сезонний","Стратегічний"},0),Settings!$H$78,Settings!$H$80,Settings!$H$82,Settings!$H$84,Settings!$H$86) | AT4: =CHOOSE(MATCH(IF($U4="","Основний",$U4),{"Трафіковий","Основний","Маржинальний","Сезонний","Стратегічний"},0),Settings!$I$78,Settings!$I$80,Settings!$I$82,Settings!$I$84,Settings!$I$86) | AV4: 1.67
B5: B7426 | C5: RAVER BAT. NIMH HR6 2BL | D5: Батарейки | E5: 2 | F5: 0.491 | G5: 8507500090 | H5: 1.3 | I5: =IFERROR(F5*Settings!$B$2*H5*IF(AND(ISNUMBER(E5),E5>1),E5,1),"") | J5: =Settings!$B$66 | K5: =IFERROR(IF(T5="","",(T5*(1-AN5)*(1-Settings!$B$17)-I5)/(T5*(1-AN5)*(1-Settings!$B$17))),"") | L5: =IFERROR(IF(T5="","",(T5*(1-AO5)*(1-Settings!$C$17)-I5)/(T5*(1-AO5)*(1-Settings!$C$17))),"") | M5: =IFERROR(IF(T5="","",(T5*(1-AP5)*(1-Settings!$D$17)-I5)/(T5*(1-AP5)*(1-Settings!$D$17))),"") | N5: =IFERROR(IF(T5="","",(T5*(1-AQ5)*(1-Settings!$F$17)-I5)/(T5*(1-AQ5)*(1-Settings!$F$17))),"") | O5: =IFERROR(IF(T5="","",(T5*(1-AR5)*(1-Settings!$G$17)-I5)/(T5*(1-AR5)*(1-Settings!$G$17))),"") | P5: =IFERROR(IF(T5="","",(T5*(1-AS5)*(1-Settings!$H$17)-I5)/(T5*(1-AS5)*(1-Settings!$H$17))),"") | Q5: =IFERROR(IF(T5="","",(T5*(1-AT5)*(1-Settings!$I$68)*(1-Settings!$I$17)-I5)/(T5*(1-AT5)*(1-Settings!$I$68)*(1-Settings!$I$17))),"") | R5: =IFERROR(IF(OR(I5="",Z5>=1,Settings!$B$17>=1,AN5>=1),"",IF(MOD(ROUND(I5/(1-Z5)/(1-Settings!$B$17)/(1-AN5),0),10)=0,ROUND(I5/(1-Z5)/(1-Settings!$B$17)/(1-AN5),0)-1,IF(MOD(ROUND(I5/(1-Z5)/(1-Settings!$B$17)/(1-AN5),0),10)<=5,FLOOR(ROUND(I5/(1-Z5)/(1-Settings!$B$17)/(1-AN5),0),10)+6,FLOOR(ROUND(I5/(1-Z5)/(1-Settings!$B$17)/(1-AN5),0),10)+9))),"") | S5: 130 | T5: =IF(S5<>"", IF(MOD(S5,10)=0,S5-1,IF(MOD(S5,10)<=5,FLOOR(S5,10)+6,FLOOR(S5,10)+9)), R5) | U5: Маржинальний | X5: =IFERROR(IF(OR(V5="",W5="",T5=""),"", IF(T5>W5,"Дорогий",IF(T5<V5,"Дешевий","У ринку"))),"") | Z5: =CHOOSE(MATCH(IF($U5="","Основний",$U5),{"Трафіковий","Основний","Маржинальний","Сезонний","Стратегічний"},0),0.16,0.19,0.24,0.23,0.28) | AA5: =CHOOSE(MATCH(IF($U5="","Основний",$U5),{"Трафіковий","Основний","Маржинальний","Сезонний","Стратегічний"},0),0.18,0.21,0.26,0.25,0.3) | AB5: =CHOOSE(MATCH(IF($U5="","Основний",$U5),{"Трафіковий","Основний","Маржинальний","Сезонний","Стратегічний"},0),0.19,0.22,0.28,0.26,0.32) | AC5: =CHOOSE(MATCH(IF($U5="","Основний",$U5),{"Трафіковий","Основний","Маржинальний","Сезонний","Стратегічний"},0),0.17,0.2,0.25,0.24,0.28) | AD5: =CHOOSE(MATCH(IF($U5="","Основний",$U5),{"Трафіковий","Основний","Маржинальний","Сезонний","Стратегічний"},0),0.18,0.21,0.26,0.25,0.3) | AE5: =CHOOSE(MATCH(IF($U5="","Основний",$U5),{"Трафіковий","Основний","Маржинальний","Сезонний","Стратегічний"},0),0.18,0.2,0.28,0.27,0.32) | AF5: =CHOOSE(MATCH(IF($U5="","Основний",$U5),{"Трафіковий","Основний","Маржинальний","Сезонний","Стратегічний"},0),0.15,0.175,0.22,0.21,0.25) | AG5: =CHOOSE(MATCH(IF($U5="","Основний",$U5),{"Трафіковий","Основний","Маржинальний","Сезонний","Стратегічний"},0),0.13,0.16,0.21,0.2,0.25) | AH5: =CHOOSE(MATCH(IF($U5="","Основний",$U5),{"Трафіковий","Основний","Маржинальний","Сезонний","Стратегічний"},0),0.15,0.18,0.23,0.22,0.27) | AI5: =CHOOSE(MATCH(IF($U5="","Основний",$U5),{"Трафіковий","Основний","Маржинальний","Сезонний","Стратегічний"},0),0.16,0.19,0.25,0.23,0.29) | AJ5: =CHOOSE(MATCH(IF($U5="","Основний",$U5),{"Трафіковий","Основний","Маржинальний","Сезонний","Стратегічний"},0),0.14,0.17,0.22,0.21,0.25) | AK5: =CHOOSE(MATCH(IF($U5="","Основний",$U5),{"Трафіковий","Основний","Маржинальний","Сезонний","Стратегічний"},0),0.15,0.18,0.23,0.22,0.27) | AL5: =CHOOSE(MATCH(IF($U5="","Основний",$U5),{"Трафіковий","Основний","Маржинальний","Сезонний","Стратегічний"},0),0.15,0.17,0.25,0.24,0.29) | AM5: =CHOOSE(MATCH(IF($U5="","Основний",$U5),{"Трафіковий","Основний","Маржинальний","Сезонний","Стратегічний"},0),0.12,0.145,0.19,0.18,0.22) | AN5: =CHOOSE(MATCH(IF($U5="","Основний",$U5),{"Трафіковий","Основний","Маржинальний","Сезонний","Стратегічний"},0),Settings!$B$78,Settings!$B$80,Settings!$B$82,Settings!$B$84,Settings!$B$86) | AO5: =CHOOSE(MATCH(IF($U5="","Основний",$U5),{"Трафіковий","Основний","Маржинальний","Сезонний","Стратегічний"},0),Settings!$C$78,Settings!$C$80,Settings!$C$82,Settings!$C$84,Settings!$C$86) | AP5: =CHOOSE(MATCH(IF($U5="","Основний",$U5),{"Трафіковий","Основний","Маржинальний","Сезонний","Стратегічний"},0),Settings!$D$78,Settings!$D$80,Settings!$D$82,Settings!$D$84,Settings!$D$86) | AQ5: =CHOOSE(MATCH(IF($U5="","Основний",$U5),{"Трафіковий","Основний","Маржинальний","Сезонний","Стратегічний"},0),Settings!$F$78,Settings!$F$80,Settings!$F$82,Settings!$F$84,Settings!$F$86) | AR5: =CHOOSE(MATCH(IF($U5="","Основний",$U5),{"Трафіковий","Основний","Маржинальний","Сезонний","Стратегічний"},0),Settings!$G$78,Settings!$G$80,Settings!$G$82,Settings!$G$84,Settings!$G$86) | AS5: =CHOOSE(MATCH(IF($U5="","Основний",$U5),{"Трафіковий","Основний","Маржинальний","Сезонний","Стратегічний"},0),Settings!$H$78,Settings!$H$80,Settings!$H$82,Settings!$H$84,Settings!$H$86) | AT5: =CHOOSE(MATCH(IF($U5="","Основний",$U5),{"Трафіковий","Основний","Маржинальний","Сезонний","Стратегічний"},0),Settings!$I$78,Settings!$I$80,Settings!$I$82,Settings!$I$84,Settings!$I$86) | AV5: 1.4
B6: B7414 | C6: RAVER BAT. NIMH HR03 2BL | D6: Батарейки | E6: 2 | F6: 0.428 | G6: 8507500090 | H6: 1.3 | I6: =IFERROR(F6*Settings!$B$2*H6*IF(AND(ISNUMBER(E6),E6>1),E6,1),"") | J6: =Settings!$B$66 | K6: =IFERROR(IF(T6="","",(T6*(1-AN6)*(1-Settings!$B$17)-I6)/(T6*(1-AN6)*(1-Settings!$B$17))),"") | L6: =IFERROR(IF(T6="","",(T6*(1-AO6)*(1-Settings!$C$17)-I6)/(T6*(1-AO6)*(1-Settings!$C$17))),"") | M6: =IFERROR(IF(T6="","",(T6*(1-AP6)*(1-Settings!$D$17)-I6)/(T6*(1-AP6)*(1-Settings!$D$17))),"") | N6: =IFERROR(IF(T6="","",(T6*(1-AQ6)*(1-Settings!$F$17)-I6)/(T6*(1-AQ6)*(1-Settings!$F$17))),"") | O6: =IFERROR(IF(T6="","",(T6*(1-AR6)*(1-Settings!$G$17)-I6)/(T6*(1-AR6)*(1-Settings!$G$17))),"") | P6: =IFERROR(IF(T6="","",(T6*(1-AS6)*(1-Settings!$H$17)-I6)/(T6*(1-AS6)*(1-Settings!$H$17))),"") | Q6: =IFERROR(IF(T6="","",(T6*(1-AT6)*(1-Settings!$I$68)*(1-Settings!$I$17)-I6)/(T6*(1-AT6)*(1-Settings!$I$68)*(1-Settings!$I$17))),"") | R6: =IFERROR(IF(OR(I6="",Z6>=1,Settings!$B$17>=1,AN6>=1),"",IF(MOD(ROUND(I6/(1-Z6)/(1-Settings!$B$17)/(1-AN6),0),10)=0,ROUND(I6/(1-Z6)/(1-Settings!$B$17)/(1-AN6),0)-1,IF(MOD(ROUND(I6/(1-Z6)/(1-Settings!$B$17)/(1-AN6),0),10)<=5,FLOOR(ROUND(I6/(1-Z6)/(1-Settings!$B$17)/(1-AN6),0),10)+6,FLOOR(ROUND(I6/(1-Z6)/(1-Settings!$B$17)/(1-AN6),0),10)+9))),"") | S6: 120 | T6: =IF(S6<>"", IF(MOD(S6,10)=0,S6-1,IF(MOD(S6,10)<=5,FLOOR(S6,10)+6,FLOOR(S6,10)+9)), R6) | U6: Маржинальний | X6: =IFERROR(IF(OR(V6="",W6="",T6=""),"", IF(T6>W6,"Дорогий",IF(T6<V6,"Дешевий","У ринку"))),"") | Z6: =CHOOSE(MATCH(IF($U6="","Основний",$U6),{"Трафіковий","Основний","Маржинальний","Сезонний","Стратегічний"},0),0.16,0.19,0.24,0.23,0.28) | AA6: =CHOOSE(MATCH(IF($U6="","Основний",$U6),{"Трафіковий","Основний","Маржинальний","Сезонний","Стратегічний"},0),0.18,0.21,0.26,0.25,0.3) | AB6: =CHOOSE(MATCH(IF($U6="","Основний",$U6),{"Трафіковий","Основний","Маржинальний","Сезонний","Стратегічний"},0),0.19,0.22,0.28,0.26,0.32) | AC6: =CHOOSE(MATCH(IF($U6="","Основний",$U6),{"Трафіковий","Основний","Маржинальний","Сезонний","Стратегічний"},0),0.17,0.2,0.25,0.24,0.28) | AD6: =CHOOSE(MATCH(IF($U6="","Основний",$U6),{"Трафіковий","Основний","Маржинальний","Сезонний","Стратегічний"},0),0.18,0.21,0.26,0.25,0.3) | AE6: =CHOOSE(MATCH(IF($U6="","Основний",$U6),{"Трафіковий","Основний","Маржинальний","Сезонний","Стратегічний"},0),0.18,0.2,0.28,0.27,0.32) | AF6: =CHOOSE(MATCH(IF($U6="","Основний",$U6),{"Трафіковий","Основний","Маржинальний","Сезонний","Стратегічний"},0),0.15,0.175,0.22,0.21,0.25) | AG6: =CHOOSE(MATCH(IF($U6="","Основний",$U6),{"Трафіковий","Основний","Маржинальний","Сезонний","Стратегічний"},0),0.13,0.16,0.21,0.2,0.25) | AH6: =CHOOSE(MATCH(IF($U6="","Основний",$U6),{"Трафіковий","Основний","Маржинальний","Сезонний","Стратегічний"},0),0.15,0.18,0.23,0.22,0.27) | AI6: =CHOOSE(MATCH(IF($U6="","Основний",$U6),{"Трафіковий","Основний","Маржинальний","Сезонний","Стратегічний"},0),0.16,0.19,0.25,0.23,0.29) | AJ6: =CHOOSE(MATCH(IF($U6="","Основний",$U6),{"Трафіковий","Основний","Маржинальний","Сезонний","Стратегічний"},0),0.14,0.17,0.22,0.21,0.25) | AK6: =CHOOSE(MATCH(IF($U6="","Основний",$U6),{"Трафіковий","Основний","Маржинальний","Сезонний","Стратегічний"},0),0.15,0.18,0.23,0.22,0.27) | AL6: =CHOOSE(MATCH(IF($U6="","Основний",$U6),{"Трафіковий","Основний","Маржинальний","Сезонний","Стратегічний"},0),0.15,0.17,0.25,0.24,0.29) | AM6: =CHOOSE(MATCH(IF($U6="","Основний",$U6),{"Трафіковий","Основний","Маржинальний","Сезонний","Стратегічний"},0),0.12,0.145,0.19,0.18,0.22) | AN6: =CHOOSE(MATCH(IF($U6="","Основний",$U6),{"Трафіковий","Основний","Маржинальний","Сезонний","Стратегічний"},0),Settings!$B$78,Settings!$B$80,Settings!$B$82,Settings!$B$84,Settings!$B$86) | AO6: =CHOOSE(MATCH(IF($U6="","Основний",$U6),{"Трафіковий","Основний","Маржинальний","Сезонний","Стратегічний"},0),Settings!$C$78,Settings!$C$80,Settings!$C$82,Settings!$C$84,Settings!$C$86) | AP6: =CHOOSE(MATCH(IF($U6="","Основний",$U6),{"Трафіковий","Основний","Маржинальний","Сезонний","Стратегічний"},0),Settings!$D$78,Settings!$D$80,Settings!$D$82,Settings!$D$84,Settings!$D$86) | AQ6: =CHOOSE(MATCH(IF($U6="","Основний",$U6),{"Трафіковий","Основний","Маржинальний","Сезонний","Стратегічний"},0),Settings!$F$78,Settings!$F$80,Settings!$F$82,Settings!$F$84,Settings!$F$86) | AR6: =CHOOSE(MATCH(IF($U6="","Основний",$U6),{"Трафіковий","Основний","Маржинальний","Сезонний","Стратегічний"},0),Settings!$G$78,Settings!$G$80,Settings!$G$82,Settings!$G$84,Settings!$G$86) | AS6: =CHOOSE(MATCH(IF($U6="","Основний",$U6),{"Трафіковий","Основний","Маржинальний","Сезонний","Стратегічний"},0),Settings!$H$78,Settings!$H$80,Settings!$H$82,Settings!$H$84,Settings!$H$86) | AT6: =CHOOSE(MATCH(IF($U6="","Основний",$U6),{"Трафіковий","Основний","Маржинальний","Сезонний","Стратегічний"},0),Settings!$I$78,Settings!$I$80,Settings!$I$82,Settings!$I$84,Settings!$I$86) | AV6: 1.4
A7: SELL OUT | B7: B7316 | C7: RAVER BAT. WATCH CR2016, 5BL | D7: Батарейки | E7: 5 | F7: 0.083 | G7: 8506503000 | H7: 1.35 | I7: =IFERROR(F7*Settings!$B$2*H7*IF(AND(ISNUMBER(E7),E7>1),E7,1),"") | J7: =Settings!$B$66 | K7: =IFERROR(IF(T7="","",(T7*(1-AN7)*(1-Settings!$B$17)-I7)/(T7*(1-AN7)*(1-Settings!$B$17))),"") | L7: =IFERROR(IF(T7="","",(T7*(1-AO7)*(1-Settings!$C$17)-I7)/(T7*(1-AO7)*(1-Settings!$C$17))),"") | M7: =IFERROR(IF(T7="","",(T7*(1-AP7)*(1-Settings!$D$17)-I7)/(T7*(1-AP7)*(1-Settings!$D$17))),"") | N7: =IFERROR(IF(T7="","",(T7*(1-AQ7)*(1-Settings!$F$17)-I7)/(T7*(1-AQ7)*(1-Settings!$F$17))),"") | O7: =IFERROR(IF(T7="","",(T7*(1-AR7)*(1-Settings!$G$17)-I7)/(T7*(1-AR7)*(1-Settings!$G$17))),"") | P7: =IFERROR(IF(T7="","",(T7*(1-AS7)*(1-Settings!$H$17)-I7)/(T7*(1-AS7)*(1-Settings!$H$17))),"") | Q7: =IFERROR(IF(T7="","",(T7*(1-AT7)*(1-Settings!$I$68)*(1-Settings!$I$17)-I7)/(T7*(1-AT7)*(1-Settings!$I$68)*(1-Settings!$I$17))),"") | R7: =IFERROR(IF(OR(I7="",Z7>=1,Settings!$B$17>=1,AN7>=1),"",IF(MOD(ROUND(I7/(1-Z7)/(1-Settings!$B$17)/(1-AN7),0),10)=0,ROUND(I7/(1-Z7)/(1-Settings!$B$17)/(1-AN7),0)-1,IF(MOD(ROUND(I7/(1-Z7)/(1-Settings!$B$17)/(1-AN7),0),10)<=5,FLOOR(ROUND(I7/(1-Z7)/(1-Settings!$B$17)/(1-AN7),0),10)+6,FLOOR(ROUND(I7/(1-Z7)/(1-Settings!$B$17)/(1-AN7),0),10)+9))),"") | S7: 69 | T7: =IF(S7<>"", IF(MOD(S7,10)=0,S7-1,IF(MOD(S7,10)<=5,FLOOR(S7,10)+6,FLOOR(S7,10)+9)), R7) | U7: Маржинальний | X7: =IFERROR(IF(OR(V7="",W7="",T7=""),"", IF(T7>W7,"Дорогий",IF(T7<V7,"Дешевий","У ринку"))),"") | Z7: =CHOOSE(MATCH(IF($U7="","Основний",$U7),{"Трафіковий","Основний","Маржинальний","Сезонний","Стратегічний"},0),0.16,0.19,0.24,0.23,0.28) | AA7: =CHOOSE(MATCH(IF($U7="","Основний",$U7),{"Трафіковий","Основний","Маржинальний","Сезонний","Стратегічний"},0),0.18,0.21,0.26,0.25,0.3) | AB7: =CHOOSE(MATCH(IF($U7="","Основний",$U7),{"Трафіковий","Основний","Маржинальний","Сезонний","Стратегічний"},0),0.19,0.22,0.28,0.26,0.32) | AC7: =CHOOSE(MATCH(IF($U7="","Основний",$U7),{"Трафіковий","Основний","Маржинальний","Сезонний","Стратегічний"},0),0.17,0.2,0.25,0.24,0.28) | AD7: =CHOOSE(MATCH(IF($U7="","Основний",$U7),{"Трафіковий","Основний","Маржинальний","Сезонний","Стратегічний"},0),0.18,0.21,0.26,0.25,0.3) | AE7: =CHOOSE(MATCH(IF($U7="","Основний",$U7),{"Трафіковий","Основний","Маржинальний","Сезонний","Стратегічний"},0),0.18,0.2,0.28,0.27,0.32) | AF7: =CHOOSE(MATCH(IF($U7="","Основний",$U7),{"Трафіковий","Основний","Маржинальний","Сезонний","Стратегічний"},0),0.15,0.175,0.22,0.21,0.25) | AG7: =CHOOSE(MATCH(IF($U7="","Основний",$U7),{"Трафіковий","Основний","Маржинальний","Сезонний","Стратегічний"},0),0.13,0.16,0.21,0.2,0.25) | AH7: =CHOOSE(MATCH(IF($U7="","Основний",$U7),{"Трафіковий","Основний","Маржинальний","Сезонний","Стратегічний"},0),0.15,0.18,0.23,0.22,0.27) | AI7: =CHOOSE(MATCH(IF($U7="","Основний",$U7),{"Трафіковий","Основний","Маржинальний","Сезонний","Стратегічний"},0),0.16,0.19,0.25,0.23,0.29) | AJ7: =CHOOSE(MATCH(IF($U7="","Основний",$U7),{"Трафіковий","Основний","Маржинальний","Сезонний","Стратегічний"},0),0.14,0.17,0.22,0.21,0.25) | AK7: =CHOOSE(MATCH(IF($U7="","Основний",$U7),{"Трафіковий","Основний","Маржинальний","Сезонний","Стратегічний"},0),0.15,0.18,0.23,0.22,0.27) | AL7: =CHOOSE(MATCH(IF($U7="","Основний",$U7),{"Трафіковий","Основний","Маржинальний","Сезонний","Стратегічний"},0),0.15,0.17,0.25,0.24,0.29) | AM7: =CHOOSE(MATCH(IF($U7="","Основний",$U7),{"Трафіковий","Основний","Маржинальний","Сезонний","Стратегічний"},0),0.12,0.145,0.19,0.18,0.22) | AN7: =CHOOSE(MATCH(IF($U7="","Основний",$U7),{"Трафіковий","Основний","Маржинальний","Сезонний","Стратегічний"},0),Settings!$B$78,Settings!$B$80,Settings!$B$82,Settings!$B$84,Settings!$B$86) | AO7: =CHOOSE(MATCH(IF($U7="","Основний",$U7),{"Трафіковий","Основний","Маржинальний","Сезонний","Стратегічний"},0),Settings!$C$78,Settings!$C$80,Settings!$C$82,Settings!$C$84,Settings!$C$86) | AP7: =CHOOSE(MATCH(IF($U7="","Основний",$U7),{"Трафіковий","Основний","Маржинальний","Сезонний","Стратегічний"},0),Settings!$D$78,Settings!$D$80,Settings!$D$82,Settings!$D$84,Settings!$D$86) | AQ7: =CHOOSE(MATCH(IF($U7="","Основний",$U7),{"Трафіковий","Основний","Маржинальний","Сезонний","Стратегічний"},0),Settings!$F$78,Settings!$F$80,Settings!$F$82,Settings!$F$84,Settings!$F$86) | AR7: =CHOOSE(MATCH(IF($U7="","Основний",$U7),{"Трафіковий","Основний","Маржинальний","Сезонний","Стратегічний"},0),Settings!$G$78,Settings!$G$80,Settings!$G$82,Settings!$G$84,Settings!$G$86) | AS7: =CHOOSE(MATCH(IF($U7="","Основний",$U7),{"Трафіковий","Основний","Маржинальний","Сезонний","Стратегічний"},0),Settings!$H$78,Settings!$H$80,Settings!$H$82,Settings!$H$84,Settings!$H$86) | AT7: =CHOOSE(MATCH(IF($U7="","Основний",$U7),{"Трафіковий","Основний","Маржинальний","Сезонний","Стратегічний"},0),Settings!$I$78,Settings!$I$80,Settings!$I$82,Settings!$I$84,Settings!$I$86) | AV7: 1.67
A8: SELL OUT | B8: B7325 | C8: RAVER BAT. WATCH CR2025, 5BL | D8: Батарейки | E8: 5 | F8: 0.089 | G8: 8506503000 | H8: 1.35 | I8: =IFERROR(F8*Settings!$B$2*H8*IF(AND(ISNUMBER(E8),E8>1),E8,1),"") | J8: =Settings!$B$66 | K8: =IFERROR(IF(T8="","",(T8*(1-AN8)*(1-Settings!$B$17)-I8)/(T8*(1-AN8)*(1-Settings!$B$17))),"") | L8: =IFERROR(IF(T8="","",(T8*(1-AO8)*(1-Settings!$C$17)-I8)/(T8*(1-AO8)*(1-Settings!$C$17))),"") | M8: =IFERROR(IF(T8="","",(T8*(1-AP8)*(1-Settings!$D$17)-I8)/(T8*(1-AP8)*(1-Settings!$D$17))),"") | N8: =IFERROR(IF(T8="","",(T8*(1-AQ8)*(1-Settings!$F$17)-I8)/(T8*(1-AQ8)*(1-Settings!$F$17))),"") | O8: =IFERROR(IF(T8="","",(T8*(1-AR8)*(1-Settings!$G$17)-I8)/(T8*(1-AR8)*(1-Settings!$G$17))),"") | P8: =IFERROR(IF(T8="","",(T8*(1-AS8)*(1-Settings!$H$17)-I8)/(T8*(1-AS8)*(1-Settings!$H$17))),"") | Q8: =IFERROR(IF(T8="","",(T8*(1-AT8)*(1-Settings!$I$68)*(1-Settings!$I$17)-I8)/(T8*(1-AT8)*(1-Settings!$I$68)*(1-Settings!$I$17))),"") | R8: =IFERROR(IF(OR(I8="",Z8>=1,Settings!$B$17>=1,AN8>=1),"",IF(MOD(ROUND(I8/(1-Z8)/(1-Settings!$B$17)/(1-AN8),0),10)=0,ROUND(I8/(1-Z8)/(1-Settings!$B$17)/(1-AN8),0)-1,IF(MOD(ROUND(I8/(1-Z8)/(1-Settings!$B$17)/(1-AN8),0),10)<=5,FLOOR(ROUND(I8/(1-Z8)/(1-Settings!$B$17)/(1-AN8),0),10)+6,FLOOR(ROUND(I8/(1-Z8)/(1-Settings!$B$17)/(1-AN8),0),10)+9))),"") | S8: 70 | T8: =IF(S8<>"", IF(MOD(S8,10)=0,S8-1,IF(MOD(S8,10)<=5,FLOOR(S8,10)+6,FLOOR(S8,10)+9)), R8) | U8: Маржинальний | X8: =IFERROR(IF(OR(V8="",W8="",T8=""),"", IF(T8>W8,"Дорогий",IF(T8<V8,"Дешевий","У ринку"))),"") | Z8: =CHOOSE(MATCH(IF($U8="","Основний",$U8),{"Трафіковий","Основний","Маржинальний","Сезонний","Стратегічний"},0),0.16,0.19,0.24,0.23,0.28) | AA8: =CHOOSE(MATCH(IF($U8="","Основний",$U8),{"Трафіковий","Основний","Маржинальний","Сезонний","Стратегічний"},0),0.18,0.21,0.26,0.25,0.3) | AB8: =CHOOSE(MATCH(IF($U8="","Основний",$U8),{"Трафіковий","Основний","Маржинальний","Сезонний","Стратегічний"},0),0.19,0.22,0.28,0.26,0.32) | AC8: =CHOOSE(MATCH(IF($U8="","Основний",$U8),{"Трафіковий","Основний","Маржинальний","Сезонний","Стратегічний"},0),0.17,0.2,0.25,0.24,0.28) | AD8: =CHOOSE(MATCH(IF($U8="","Основний",$U8),{"Трафіковий","Основний","Маржинальний","Сезонний","Стратегічний"},0),0.18,0.21,0.26,0.25,0.3) | AE8: =CHOOSE(MATCH(IF($U8="","Основний",$U8),{"Трафіковий","Основний","Маржинальний","Сезонний","Стратегічний"},0),0.18,0.2,0.28,0.27,0.32) | AF8: =CHOOSE(MATCH(IF($U8="","Основний",$U8),{"Трафіковий","Основний","Маржинальний","Сезонний","Стратегічний"},0),0.15,0.175,0.22,0.21,0.25) | AG8: =CHOOSE(MATCH(IF($U8="","Основний",$U8),{"Трафіковий","Основний","Маржинальний","Сезонний","Стратегічний"},0),0.13,0.16,0.21,0.2,0.25) | AH8: =CHOOSE(MATCH(IF($U8="","Основний",$U8),{"Трафіковий","Основний","Маржинальний","Сезонний","Стратегічний"},0),0.15,0.18,0.23,0.22,0.27) | AI8: =CHOOSE(MATCH(IF($U8="","Основний",$U8),{"Трафіковий","Основний","Маржинальний","Сезонний","Стратегічний"},0),0.16,0.19,0.25,0.23,0.29) | AJ8: =CHOOSE(MATCH(IF($U8="","Основний",$U8),{"Трафіковий","Основний","Маржинальний","Сезонний","Стратегічний"},0),0.14,0.17,0.22,0.21,0.25) | AK8: =CHOOSE(MATCH(IF($U8="","Основний",$U8),{"Трафіковий","Основний","Маржинальний","Сезонний","Стратегічний"},0),0.15,0.18,0.23,0.22,0.27) | AL8: =CHOOSE(MATCH(IF($U8="","Основний",$U8),{"Трафіковий","Основний","Маржинальний","Сезонний","Стратегічний"},0),0.15,0.17,0.25,0.24,0.29) | AM8: =CHOOSE(MATCH(IF($U8="","Основний",$U8),{"Трафіковий","Основний","Маржинальний","Сезонний","Стратегічний"},0),0.12,0.145,0.19,0.18,0.22) | AN8: =CHOOSE(MATCH(IF($U8="","Основний",$U8),{"Трафіковий","Основний","Маржинальний","Сезонний","Стратегічний"},0),Settings!$B$78,Settings!$B$80,Settings!$B$82,Settings!$B$84,Settings!$B$86) | AO8: =CHOOSE(MATCH(IF($U8="","Основний",$U8),{"Трафіковий","Основний","Маржинальний","Сезонний","Стратегічний"},0),Settings!$C$78,Settings!$C$80,Settings!$C$82,Settings!$C$84,Settings!$C$86) | AP8: =CHOOSE(MATCH(IF($U8="","Основний",$U8),{"Трафіковий","Основний","Маржинальний","Сезонний","Стратегічний"},0),Settings!$D$78,Settings!$D$80,Settings!$D$82,Settings!$D$84,Settings!$D$86) | AQ8: =CHOOSE(MATCH(IF($U8="","Основний",$U8),{"Трафіковий","Основний","Маржинальний","Сезонний","Стратегічний"},0),Settings!$F$78,Settings!$F$80,Settings!$F$82,Settings!$F$84,Settings!$F$86) | AR8: =CHOOSE(MATCH(IF($U8="","Основний",$U8),{"Трафіковий","Основний","Маржинальний","Сезонний","Стратегічний"},0),Settings!$G$78,Settings!$G$80,Settings!$G$82,Settings!$G$84,Settings!$G$86) | AS8: =CHOOSE(MATCH(IF($U8="","Основний",$U8),{"Трафіковий","Основний","Маржинальний","Сезонний","Стратегічний"},0),Settings!$H$78,Settings!$H$80,Settings!$H$82,Settings!$H$84,Settings!$H$86) | AT8: =CHOOSE(MATCH(IF($U8="","Основний",$U8),{"Трафіковий","Основний","Маржинальний","Сезонний","Стратегічний"},0),Settings!$I$78,Settings!$I$80,Settings!$I$82,Settings!$I$84,Settings!$I$86) | AV8: 1.67
B9: N0322 | C9: UNI BATTERY TESTER LCD | D9: Зарядні пристрої для акумуляторів | E9: PC | F9: 2.244 | G9: 9030337000 | H9: 1.3 | I9: =IFERROR(F9*Settings!$B$2*H9*IF(AND(ISNUMBER(E9),E9>1),E9,1),"") | J9: =Settings!$B$66 | K9: =IFERROR(IF(T9="","",(T9*(1-AN9)*(1-Settings!$B$17)-I9)/(T9*(1-AN9)*(1-Settings!$B$17))),"") | L9: =IFERROR(IF(T9="","",(T9*(1-AO9)*(1-Settings!$C$17)-I9)/(T9*(1-AO9)*(1-Settings!$C$17))),"") | M9: =IFERROR(IF(T9="","",(T9*(1-AP9)*(1-Settings!$D$17)-I9)/(T9*(1-AP9)*(1-Settings!$D$17))),"") | N9: =IFERROR(IF(T9="","",(T9*(1-AQ9)*(1-Settings!$F$17)-I9)/(T9*(1-AQ9)*(1-Settings!$F$17))),"") | O9: =IFERROR(IF(T9="","",(T9*(1-AR9)*(1-Settings!$G$17)-I9)/(T9*(1-AR9)*(1-Settings!$G$17))),"") | P9: =IFERROR(IF(T9="","",(T9*(1-AS9)*(1-Settings!$H$17)-I9)/(T9*(1-AS9)*(1-Settings!$H$17))),"") | Q9: =IFERROR(IF(T9="","",(T9*(1-AT9)*(1-Settings!$I$68)*(1-Settings!$I$17)-I9)/(T9*(1-AT9)*(1-Settings!$I$68)*(1-Settings!$I$17))),"") | R9: =IFERROR(IF(OR(I9="",Z9>=1,Settings!$B$17>=1,AN9>=1),"",IF(MOD(ROUND(I9/(1-Z9)/(1-Settings!$B$17)/(1-AN9),0),10)=0,ROUND(I9/(1-Z9)/(1-Settings!$B$17)/(1-AN9),0)-1,IF(MOD(ROUND(I9/(1-Z9)/(1-Settings!$B$17)/(1-AN9),0),10)<=5,FLOOR(ROUND(I9/(1-Z9)/(1-Settings!$B$17)/(1-AN9),0),10)+6,FLOOR(ROUND(I9/(1-Z9)/(1-Settings!$B$17)/(1-AN9),0),10)+9))),"") | T9: =IF(S9<>"", IF(MOD(S9,10)=0,S9-1,IF(MOD(S9,10)<=5,FLOOR(S9,10)+6,FLOOR(S9,10)+9)), R9) | U9: Основний | X9: =IFERROR(IF(OR(V9="",W9="",T9=""),"", IF(T9>W9,"Дорогий",IF(T9<V9,"Дешевий","У ринку"))),"") | Z9: =CHOOSE(MATCH(IF($U9="","Основний",$U9),{"Трафіковий","Основний","Маржинальний","Сезонний","Стратегічний"},0),0.16,0.19,0.24,0.23,0.28) | AA9: =CHOOSE(MATCH(IF($U9="","Основний",$U9),{"Трафіковий","Основний","Маржинальний","Сезонний","Стратегічний"},0),0.18,0.21,0.26,0.25,0.3) | AB9: =CHOOSE(MATCH(IF($U9="","Основний",$U9),{"Трафіковий","Основний","Маржинальний","Сезонний","Стратегічний"},0),0.19,0.22,0.28,0.26,0.32) | AC9: =CHOOSE(MATCH(IF($U9="","Основний",$U9),{"Трафіковий","Основний","Маржинальний","Сезонний","Стратегічний"},0),0.17,0.2,0.25,0.24,0.28) | AD9: =CHOOSE(MATCH(IF($U9="","Основний",$U9),{"Трафіковий","Основний","Маржинальний","Сезонний","Стратегічний"},0),0.18,0.21,0.26,0.25,0.3) | AE9: =CHOOSE(MATCH(IF($U9="","Основний",$U9),{"Трафіковий","Основний","Маржинальний","Сезонний","Стратегічний"},0),0.18,0.2,0.28,0.27,0.32) | AF9: =CHOOSE(MATCH(IF($U9="","Основний",$U9),{"Трафіковий","Основний","Маржинальний","Сезонний","Стратегічний"},0),0.15,0.175,0.22,0.21,0.25) | AG9: =CHOOSE(MATCH(IF($U9="","Основний",$U9),{"Трафіковий","Основний","Маржинальний","Сезонний","Стратегічний"},0),0.13,0.16,0.21,0.2,0.25) | AH9: =CHOOSE(MATCH(IF($U9="","Основний",$U9),{"Трафіковий","Основний","Маржинальний","Сезонний","Стратегічний"},0),0.15,0.18,0.23,0.22,0.27) | AI9: =CHOOSE(MATCH(IF($U9="","Основний",$U9),{"Трафіковий","Основний","Маржинальний","Сезонний","Стратегічний"},0),0.16,0.19,0.25,0.23,0.29) | AJ9: =CHOOSE(MATCH(IF($U9="","Основний",$U9),{"Трафіковий","Основний","Маржинальний","Сезонний","Стратегічний"},0),0.14,0.17,0.22,0.21,0.25) | AK9: =CHOOSE(MATCH(IF($U9="","Основний",$U9),{"Трафіковий","Основний","Маржинальний","Сезонний","Стратегічний"},0),0.15,0.18,0.23,0.22,0.27) | AL9: =CHOOSE(MATCH(IF($U9="","Основний",$U9),{"Трафіковий","Основний","Маржинальний","Сезонний","Стратегічний"},0),0.15,0.17,0.25,0.24,0.29) | AM9: =CHOOSE(MATCH(IF($U9="","Основний",$U9),{"Трафіковий","Основний","Маржинальний","Сезонний","Стратегічний"},0),0.12,0.145,0.19,0.18,0.22) | AN9: =CHOOSE(MATCH(IF($U9="","Основний",$U9),{"Трафіковий","Основний","Маржинальний","Сезонний","Стратегічний"},0),Settings!$B$78,Settings!$B$80,Settings!$B$82,Settings!$B$84,Settings!$B$86) | AO9: =CHOOSE(MATCH(IF($U9="","Основний",$U9),{"Трафіковий","Основний","Маржинальний","Сезонний","Стратегічний"},0),Settings!$C$78,Settings!$C$80,Settings!$C$82,Settings!$C$84,Settings!$C$86) | AP9: =CHOOSE(MATCH(IF($U9="","Основний",$U9),{"Трафіковий","Основний","Маржинальний","Сезонний","Стратегічний"},0),Settings!$D$78,Settings!$D$80,Settings!$D$82,Settings!$D$84,Settings!$D$86) | AQ9: =CHOOSE(MATCH(IF($U9="","Основний",$U9),{"Трафіковий","Основний","Маржинальний","Сезонний","Стратегічний"},0),Settings!$F$78,Settings!$F$80,Settings!$F$82,Settings!$F$84,Settings!$F$86) | AR9: =CHOOSE(MATCH(IF($U9="","Основний",$U9),{"Трафіковий","Основний","Маржинальний","Сезонний","Стратегічний"},0),Settings!$G$78,Settings!$G$80,Settings!$G$82,Settings!$G$84,Settings!$G$86) | AS9: =CHOOSE(MATCH(IF($U9="","Основний",$U9),{"Трафіковий","Основний","Маржинальний","Сезонний","Стратегічний"},0),Settings!$H$78,Settings!$H$80,Settings!$H$82,Settings!$H$84,Settings!$H$86) | AT9: =CHOOSE(MATCH(IF($U9="","Основний",$U9),{"Трафіковий","Основний","Маржинальний","Сезонний","Стратегічний"},0),Settings!$I$78,Settings!$I$80,Settings!$I$82,Settings!$I$84,Settings!$I$86) | AV9: 1.35
B10: N9221 | C10: EMOS Universal Li-ion Battery Charger BCL-20D | D10: Зарядні пристрої для акумуляторів | E10: PC | F10: 8.901 | G10: 8504406090 | H10: 1.3 | I10: =IFERROR(F10*Settings!$B$2*H10*IF(AND(ISNUMBER(E10),E10>1),E10,1),"") | J10: =Settings!$B$66 | K10: =IFERROR(IF(T10="","",(T10*(1-AN10)*(1-Settings!$B$17)-I10)/(T10*(1-AN10)*(1-Settings!$B$17))),"") | L10: =IFERROR(IF(T10="","",(T10*(1-AO10)*(1-Settings!$C$17)-I10)/(T10*(1-AO10)*(1-Settings!$C$17))),"") | M10: =IFERROR(IF(T10="","",(T10*(1-AP10)*(1-Settings!$D$17)-I10)/(T10*(1-AP10)*(1-Settings!$D$17))),"") | N10: =IFERROR(IF(T10="","",(T10*(1-AQ10)*(1-Settings!$F$17)-I10)/(T10*(1-AQ10)*(1-Settings!$F$17))),"") | O10: =IFERROR(IF(T10="","",(T10*(1-AR10)*(1-Settings!$G$17)-I10)/(T10*(1-AR10)*(1-Settings!$G$17))),"") | P10: =IFERROR(IF(T10="","",(T10*(1-AS10)*(1-Settings!$H$17)-I10)/(T10*(1-AS10)*(1-Settings!$H$17))),"") | Q10: =IFERROR(IF(T10="","",(T10*(1-AT10)*(1-Settings!$I$68)*(1-Settings!$I$17)-I10)/(T10*(1-AT10)*(1-Settings!$I$68)*(1-Settings!$I$17))),"") | R10: =IFERROR(IF(OR(I10="",Z10>=1,Settings!$B$17>=1,AN10>=1),"",IF(MOD(ROUND(I10/(1-Z10)/(1-Settings!$B$17)/(1-AN10),0),10)=0,ROUND(I10/(1-Z10)/(1-Settings!$B$17)/(1-AN10),0)-1,IF(MOD(ROUND(I10/(1-Z10)/(1-Settings!$B$17)/(1-AN10),0),10)<=5,FLOOR(ROUND(I10/(1-Z10)/(1-Settings!$B$17)/(1-AN10),0),10)+6,FLOOR(ROUND(I10/(1-Z10)/(1-Settings!$B$17)/(1-AN10),0),10)+9))),"") | T10: =IF(S10<>"", IF(MOD(S10,10)=0,S10-1,IF(MOD(S10,10)<=5,FLOOR(S10,10)+6,FLOOR(S10,10)+9)), R10) | U10: Основний | X10: =IFERROR(IF(OR(V10="",W10="",T10=""),"", IF(T10>W10,"Дорогий",IF(T10<V10,"Дешевий","У ринку"))),"") | Z10: =CHOOSE(MATCH(IF($U10="","Основний",$U10),{"Трафіковий","Основний","Маржинальний","Сезонний","Стратегічний"},0),0.16,0.19,0.24,0.23,0.28) | AA10: =CHOOSE(MATCH(IF($U10="","Основний",$U10),{"Трафіковий","Основний","Маржинальний","Сезонний","Стратегічний"},0),0.18,0.21,0.26,0.25,0.3) | AB10: =CHOOSE(MATCH(IF($U10="","Основний",$U10),{"Трафіковий","Основний","Маржинальний","Сезонний","Стратегічний"},0),0.19,0.22,0.28,0.26,0.32) | AC10: =CHOOSE(MATCH(IF($U10="","Основний",$U10),{"Трафіковий","Основний","Маржинальний","Сезонний","Стратегічний"},0),0.17,0.2,0.25,0.24,0.28) | AD10: =CHOOSE(MATCH(IF($U10="","Основний",$U10),{"Трафіковий","Основний","Маржинальний","Сезонний","Стратегічний"},0),0.18,0.21,0.26,0.25,0.3) | AE10: =CHOOSE(MATCH(IF($U10="","Основний",$U10),{"Трафіковий","Основний","Маржинальний","Сезонний","Стратегічний"},0),0.18,0.2,0.28,0.27,0.32) | AF10: =CHOOSE(MATCH(IF($U10="","Основний",$U10),{"Трафіковий","Основний","Маржинальний","Сезонний","Стратегічний"},0),0.15,0.175,0.22,0.21,0.25) | AG10: =CHOOSE(MATCH(IF($U10="","Основний",$U10),{"Трафіковий","Основний","Маржинальний","Сезонний","Стратегічний"},0),0.13,0.16,0.21,0.2,0.25) | AH10: =CHOOSE(MATCH(IF($U10="","Основний",$U10),{"Трафіковий","Основний","Маржинальний","Сезонний","Стратегічний"},0),0.15,0.18,0.23,0.22,0.27) | AI10: =CHOOSE(MATCH(IF($U10="","Основний",$U10),{"Трафіковий","Основний","Маржинальний","Сезонний","Стратегічний"},0),0.16,0.19,0.25,0.23,0.29) | AJ10: =CHOOSE(MATCH(IF($U10="","Основний",$U10),{"Трафіковий","Основний","Маржинальний","Сезонний","Стратегічний"},0),0.14,0.17,0.22,0.21,0.25) | AK10: =CHOOSE(MATCH(IF($U10="","Основний",$U10),{"Трафіковий","Основний","Маржинальний","Сезонний","Стратегічний"},0),0.15,0.18,0.23,0.22,0.27) | AL10: =CHOOSE(MATCH(IF($U10="","Основний",$U10),{"Трафіковий","Основний","Маржинальний","Сезонний","Стратегічний"},0),0.15,0.17,0.25,0.24,0.29) | AM10: =CHOOSE(MATCH(IF($U10="","Основний",$U10),{"Трафіковий","Основний","Маржинальний","Сезонний","Стратегічний"},0),0.12,0.145,0.19,0.18,0.22) | AN10: =CHOOSE(MATCH(IF($U10="","Основний",$U10),{"Трафіковий","Основний","Маржинальний","Сезонний","Стратегічний"},0),Settings!$B$78,Settings!$B$80,Settings!$B$82,Settings!$B$84,Settings!$B$86) | AO10: =CHOOSE(MATCH(IF($U10="","Основний",$U10),{"Трафіковий","Основний","Маржинальний","Сезонний","Стратегічний"},0),Settings!$C$78,Settings!$C$80,Settings!$C$82,Settings!$C$84,Settings!$C$86) | AP10: =CHOOSE(MATCH(IF($U10="","Основний",$U10),{"Трафіковий","Основний","Маржинальний","Сезонний","Стратегічний"},0),Settings!$D$78,Settings!$D$80,Settings!$D$82,Settings!$D$84,Settings!$D$86) | AQ10: =CHOOSE(MATCH(IF($U10="","Основний",$U10),{"Трафіковий","Основний","Маржинальний","Сезонний","Стратегічний"},0),Settings!$F$78,Settings!$F$80,Settings!$F$82,Settings!$F$84,Settings!$F$86) | AR10: =CHOOSE(MATCH(IF($U10="","Основний",$U10),{"Трафіковий","Основний","Маржинальний","Сезонний","Стратегічний"},0),Settings!$G$78,Settings!$G$80,Settings!$G$82,Settings!$G$84,Settings!$G$86) | AS10: =CHOOSE(MATCH(IF($U10="","Основний",$U10),{"Трафіковий","Основний","Маржинальний","Сезонний","Стратегічний"},0),Settings!$H$78,Settings!$H$80,Settings!$H$82,Settings!$H$84,Settings!$H$86) | AT10: =CHOOSE(MATCH(IF($U10="","Основний",$U10),{"Трафіковий","Основний","Маржинальний","Сезонний","Стратегічний"},0),Settings!$I$78,Settings!$I$80,Settings!$I$82,Settings!$I$84,Settings!$I$86) | AV10: 1.35
B11: N9321 | C11: EMOS battery charger BCN-40 | D11: Зарядні пристрої для акумуляторів | E11: PC | F11: 5.105 | G11: 8504406090 | H11: 1.3 | I11: =IFERROR(F11*Settings!$B$2*H11*IF(AND(ISNUMBER(E11),E11>1),E11,1),"") | J11: =Settings!$B$66 | K11: =IFERROR(IF(T11="","",(T11*(1-AN11)*(1-Settings!$B$17)-I11)/(T11*(1-AN11)*(1-Settings!$B$17))),"") | L11: =IFERROR(IF(T11="","",(T11*(1-AO11)*(1-Settings!$C$17)-I11)/(T11*(1-AO11)*(1-Settings!$C$17))),"") | M11: =IFERROR(IF(T11="","",(T11*(1-AP11)*(1-Settings!$D$17)-I11)/(T11*(1-AP11)*(1-Settings!$D$17))),"") | N11: =IFERROR(IF(T11="","",(T11*(1-AQ11)*(1-Settings!$F$17)-I11)/(T11*(1-AQ11)*(1-Settings!$F$17))),"") | O11: =IFERROR(IF(T11="","",(T11*(1-AR11)*(1-Settings!$G$17)-I11)/(T11*(1-AR11)*(1-Settings!$G$17))),"") | P11: =IFERROR(IF(T11="","",(T11*(1-AS11)*(1-Settings!$H$17)-I11)/(T11*(1-AS11)*(1-Settings!$H$17))),"") | Q11: =IFERROR(IF(T11="","",(T11*(1-AT11)*(1-Settings!$I$68)*(1-Settings!$I$17)-I11)/(T11*(1-AT11)*(1-Settings!$I$68)*(1-Settings!$I$17))),"") | R11: =IFERROR(IF(OR(I11="",Z11>=1,Settings!$B$17>=1,AN11>=1),"",IF(MOD(ROUND(I11/(1-Z11)/(1-Settings!$B$17)/(1-AN11),0),10)=0,ROUND(I11/(1-Z11)/(1-Settings!$B$17)/(1-AN11),0)-1,IF(MOD(ROUND(I11/(1-Z11)/(1-Settings!$B$17)/(1-AN11),0),10)<=5,FLOOR(ROUND(I11/(1-Z11)/(1-Settings!$B$17)/(1-AN11),0),10)+6,FLOOR(ROUND(I11/(1-Z11)/(1-Settings!$B$17)/(1-AN11),0),10)+9))),"") | T11: =IF(S11<>"", IF(MOD(S11,10)=0,S11-1,IF(MOD(S11,10)<=5,FLOOR(S11,10)+6,FLOOR(S11,10)+9)), R11) | U11: Основний | X11: =IFERROR(IF(OR(V11="",W11="",T11=""),"", IF(T11>W11,"Дорогий",IF(T11<V11,"Дешевий","У ринку"))),"") | Z11: =CHOOSE(MATCH(IF($U11="","Основний",$U11),{"Трафіковий","Основний","Маржинальний","Сезонний","Стратегічний"},0),0.16,0.19,0.24,0.23,0.28) | AA11: =CHOOSE(MATCH(IF($U11="","Основний",$U11),{"Трафіковий","Основний","Маржинальний","Сезонний","Стратегічний"},0),0.18,0.21,0.26,0.25,0.3) | AB11: =CHOOSE(MATCH(IF($U11="","Основний",$U11),{"Трафіковий","Основний","Маржинальний","Сезонний","Стратегічний"},0),0.19,0.22,0.28,0.26,0.32) | AC11: =CHOOSE(MATCH(IF($U11="","Основний",$U11),{"Трафіковий","Основний","Маржинальний","Сезонний","Стратегічний"},0),0.17,0.2,0.25,0.24,0.28) | AD11: =CHOOSE(MATCH(IF($U11="","Основний",$U11),{"Трафіковий","Основний","Маржинальний","Сезонний","Стратегічний"},0),0.18,0.21,0.26,0.25,0.3) | AE11: =CHOOSE(MATCH(IF($U11="","Основний",$U11),{"Трафіковий","Основний","Маржинальний","Сезонний","Стратегічний"},0),0.18,0.2,0.28,0.27,0.32) | AF11: =CHOOSE(MATCH(IF($U11="","Основний",$U11),{"Трафіковий","Основний","Маржинальний","Сезонний","Стратегічний"},0),0.15,0.175,0.22,0.21,0.25) | AG11: =CHOOSE(MATCH(IF($U11="","Основний",$U11),{"Трафіковий","Основний","Маржинальний","Сезонний","Стратегічний"},0),0.13,0.16,0.21,0.2,0.25) | AH11: =CHOOSE(MATCH(IF($U11="","Основний",$U11),{"Трафіковий","Основний","Маржинальний","Сезонний","Стратегічний"},0),0.15,0.18,0.23,0.22,0.27) | AI11: =CHOOSE(MATCH(IF($U11="","Основний",$U11),{"Трафіковий","Основний","Маржинальний","Сезонний","Стратегічний"},0),0.16,0.19,0.25,0.23,0.29) | AJ11: =CHOOSE(MATCH(IF($U11="","Основний",$U11),{"Трафіковий","Основний","Маржинальний","Сезонний","Стратегічний"},0),0.14,0.17,0.22,0.21,0.25) | AK11: =CHOOSE(MATCH(IF($U11="","Основний",$U11),{"Трафіковий","Основний","Маржинальний","Сезонний","Стратегічний"},0),0.15,0.18,0.23,0.22,0.27) | AL11: =CHOOSE(MATCH(IF($U11="","Основний",$U11),{"Трафіковий","Основний","Маржинальний","Сезонний","Стратегічний"},0),0.15,0.17,0.25,0.24,0.29) | AM11: =CHOOSE(MATCH(IF($U11="","Основний",$U11),{"Трафіковий","Основний","Маржинальний","Сезонний","Стратегічний"},0),0.12,0.145,0.19,0.18,0.22) | AN11: =CHOOSE(MATCH(IF($U11="","Основний",$U11),{"Трафіковий","Основний","Маржинальний","Сезонний","Стратегічний"},0),Settings!$B$78,Settings!$B$80,Settings!$B$82,Settings!$B$84,Settings!$B$86) | AO11: =CHOOSE(MATCH(IF($U11="","Основний",$U11),{"Трафіковий","Основний","Маржинальний","Сезонний","Стратегічний"},0),Settings!$C$78,Settings!$C$80,Settings!$C$82,Settings!$C$84,Settings!$C$86) | AP11: =CHOOSE(MATCH(IF($U11="","Основний",$U11),{"Трафіковий","Основний","Маржинальний","Сезонний","Стратегічний"},0),Settings!$D$78,Settings!$D$80,Settings!$D$82,Settings!$D$84,Settings!$D$86) | AQ11: =CHOOSE(MATCH(IF($U11="","Основний",$U11),{"Трафіковий","Основний","Маржинальний","Сезонний","Стратегічний"},0),Settings!$F$78,Settings!$F$80,Settings!$F$82,Settings!$F$84,Settings!$F$86) | AR11: =CHOOSE(MATCH(IF($U11="","Основний",$U11),{"Трафіковий","Основний","Маржинальний","Сезонний","Стратегічний"},0),Settings!$G$78,Settings!$G$80,Settings!$G$82,Settings!$G$84,Settings!$G$86) | AS11: =CHOOSE(MATCH(IF($U11="","Основний",$U11),{"Трафіковий","Основний","Маржинальний","Сезонний","Стратегічний"},0),Settings!$H$78,Settings!$H$80,Settings!$H$82,Settings!$H$84,Settings!$H$86) | AT11: =CHOOSE(MATCH(IF($U11="","Основний",$U11),{"Трафіковий","Основний","Маржинальний","Сезонний","Стратегічний"},0),Settings!$I$78,Settings!$I$80,Settings!$I$82,Settings!$I$84,Settings!$I$86) | AV11: 1.35
B12: N9361 | C12: EMOS universal battery charger BCN-60U | D12: Зарядні пристрої для акумуляторів | E12: PC | F12: 9.842 | G12: 8504406090 | H12: 1.3 | I12: =IFERROR(F12*Settings!$B$2*H12*IF(AND(ISNUMBER(E12),E12>1),E12,1),"") | J12: =Settings!$B$66 | K12: =IFERROR(IF(T12="","",(T12*(1-AN12)*(1-Settings!$B$17)-I12)/(T12*(1-AN12)*(1-Settings!$B$17))),"") | L12: =IFERROR(IF(T12="","",(T12*(1-AO12)*(1-Settings!$C$17)-I12)/(T12*(1-AO12)*(1-Settings!$C$17))),"") | M12: =IFERROR(IF(T12="","",(T12*(1-AP12)*(1-Settings!$D$17)-I12)/(T12*(1-AP12)*(1-Settings!$D$17))),"") | N12: =IFERROR(IF(T12="","",(T12*(1-AQ12)*(1-Settings!$F$17)-I12)/(T12*(1-AQ12)*(1-Settings!$F$17))),"") | O12: =IFERROR(IF(T12="","",(T12*(1-AR12)*(1-Settings!$G$17)-I12)/(T12*(1-AR12)*(1-Settings!$G$17))),"") | P12: =IFERROR(IF(T12="","",(T12*(1-AS12)*(1-Settings!$H$17)-I12)/(T12*(1-AS12)*(1-Settings!$H$17))),"") | Q12: =IFERROR(IF(T12="","",(T12*(1-AT12)*(1-Settings!$I$68)*(1-Settings!$I$17)-I12)/(T12*(1-AT12)*(1-Settings!$I$68)*(1-Settings!$I$17))),"") | R12: =IFERROR(IF(OR(I12="",Z12>=1,Settings!$B$17>=1,AN12>=1),"",IF(MOD(ROUND(I12/(1-Z12)/(1-Settings!$B$17)/(1-AN12),0),10)=0,ROUND(I12/(1-Z12)/(1-Settings!$B$17)/(1-AN12),0)-1,IF(MOD(ROUND(I12/(1-Z12)/(1-Settings!$B$17)/(1-AN12),0),10)<=5,FLOOR(ROUND(I12/(1-Z12)/(1-Settings!$B$17)/(1-AN12),0),10)+6,FLOOR(ROUND(I12/(1-Z12)/(1-Settings!$B$17)/(1-AN12),0),10)+9))),"") | T12: =IF(S12<>"", IF(MOD(S12,10)=0,S12-1,IF(MOD(S12,10)<=5,FLOOR(S12,10)+6,FLOOR(S12,10)+9)), R12) | U12: Основний | X12: =IFERROR(IF(OR(V12="",W12="",T12=""),"", IF(T12>W12,"Дорогий",IF(T12<V12,"Дешевий","У ринку"))),"") | Z12: =CHOOSE(MATCH(IF($U12="","Основний",$U12),{"Трафіковий","Основний","Маржинальний","Сезонний","Стратегічний"},0),0.16,0.19,0.24,0.23,0.28) | AA12: =CHOOSE(MATCH(IF($U12="","Основний",$U12),{"Трафіковий","Основний","Маржинальний","Сезонний","Стратегічний"},0),0.18,0.21,0.26,0.25,0.3) | AB12: =CHOOSE(MATCH(IF($U12="","Основний",$U12),{"Трафіковий","Основний","Маржинальний","Сезонний","Стратегічний"},0),0.19,0.22,0.28,0.26,0.32) | AC12: =CHOOSE(MATCH(IF($U12="","Основний",$U12),{"Трафіковий","Основний","Маржинальний","Сезонний","Стратегічний"},0),0.17,0.2,0.25,0.24,0.28) | AD12: =CHOOSE(MATCH(IF($U12="","Основний",$U12),{"Трафіковий","Основний","Маржинальний","Сезонний","Стратегічний"},0),0.18,0.21,0.26,0.25,0.3) | AE12: =CHOOSE(MATCH(IF($U12="","Основний",$U12),{"Трафіковий","Основний","Маржинальний","Сезонний","Стратегічний"},0),0.18,0.2,0.28,0.27,0.32) | AF12: =CHOOSE(MATCH(IF($U12="","Основний",$U12),{"Трафіковий","Основний","Маржинальний","Сезонний","Стратегічний"},0),0.15,0.175,0.22,0.21,0.25) | AG12: =CHOOSE(MATCH(IF($U12="","Основний",$U12),{"Трафіковий","Основний","Маржинальний","Сезонний","Стратегічний"},0),0.13,0.16,0.21,0.2,0.25) | AH12: =CHOOSE(MATCH(IF($U12="","Основний",$U12),{"Трафіковий","Основний","Маржинальний","Сезонний","Стратегічний"},0),0.15,0.18,0.23,0.22,0.27) | AI12: =CHOOSE(MATCH(IF($U12="","Основний",$U12),{"Трафіковий","Основний","Маржинальний","Сезонний","Стратегічний"},0),0.16,0.19,0.25,0.23,0.29) | AJ12: =CHOOSE(MATCH(IF($U12="","Основний",$U12),{"Трафіковий","Основний","Маржинальний","Сезонний","Стратегічний"},0),0.14,0.17,0.22,0.21,0.25) | AK12: =CHOOSE(MATCH(IF($U12="","Основний",$U12),{"Трафіковий","Основний","Маржинальний","Сезонний","Стратегічний"},0),0.15,0.18,0.23,0.22,0.27) | AL12: =CHOOSE(MATCH(IF($U12="","Основний",$U12),{"Трафіковий","Основний","Маржинальний","Сезонний","Стратегічний"},0),0.15,0.17,0.25,0.24,0.29) | AM12: =CHOOSE(MATCH(IF($U12="","Основний",$U12),{"Трафіковий","Основний","Маржинальний","Сезонний","Стратегічний"},0),0.12,0.145,0.19,0.18,0.22) | AN12: =CHOOSE(MATCH(IF($U12="","Основний",$U12),{"Трафіковий","Основний","Маржинальний","Сезонний","Стратегічний"},0),Settings!$B$78,Settings!$B$80,Settings!$B$82,Settings!$B$84,Settings!$B$86) | AO12: =CHOOSE(MATCH(IF($U12="","Основний",$U12),{"Трафіковий","Основний","Маржинальний","Сезонний","Стратегічний"},0),Settings!$C$78,Settings!$C$80,Settings!$C$82,Settings!$C$84,Settings!$C$86) | AP12: =CHOOSE(MATCH(IF($U12="","Основний",$U12),{"Трафіковий","Основний","Маржинальний","Сезонний","Стратегічний"},0),Settings!$D$78,Settings!$D$80,Settings!$D$82,Settings!$D$84,Settings!$D$86) | AQ12: =CHOOSE(MATCH(IF($U12="","Основний",$U12),{"Трафіковий","Основний","Маржинальний","Сезонний","Стратегічний"},0),Settings!$F$78,Settings!$F$80,Settings!$F$82,Settings!$F$84,Settings!$F$86) | AR12: =CHOOSE(MATCH(IF($U12="","Основний",$U12),{"Трафіковий","Основний","Маржинальний","Сезонний","Стратегічний"},0),Settings!$G$78,Settings!$G$80,Settings!$G$82,Settings!$G$84,Settings!$G$86) | AS12: =CHOOSE(MATCH(IF($U12="","Основний",$U12),{"Трафіковий","Основний","Маржинальний","Сезонний","Стратегічний"},0),Settings!$H$78,Settings!$H$80,Settings!$H$82,Settings!$H$84,Settings!$H$86) | AT12: =CHOOSE(MATCH(IF($U12="","Основний",$U12),{"Трафіковий","Основний","Маржинальний","Сезонний","Стратегічний"},0),Settings!$I$78,Settings!$I$80,Settings!$I$82,Settings!$I$84,Settings!$I$86) | AV12: 1.35
B13: P2311 | C13: LED RECHARGEABLE FLASHLIGHT 300LM | D13: Ліхтарі | E13: PC | F13: 11.483 | G13: 8513100000 | H13: 1.4 | I13: =IFERROR(F13*Settings!$B$2*H13*IF(AND(ISNUMBER(E13),E13>1),E13,1),"") | J13: =Settings!$B$66 | K13: =IFERROR(IF(T13="","",(T13*(1-AN13)*(1-Settings!$B$17)-I13)/(T13*(1-AN13)*(1-Settings!$B$17))),"") | L13: =IFERROR(IF(T13="","",(T13*(1-AO13)*(1-Settings!$C$17)-I13)/(T13*(1-AO13)*(1-Settings!$C$17))),"") | M13: =IFERROR(IF(T13="","",(T13*(1-AP13)*(1-Settings!$D$17)-I13)/(T13*(1-AP13)*(1-Settings!$D$17))),"") | N13: =IFERROR(IF(T13="","",(T13*(1-AQ13)*(1-Settings!$F$17)-I13)/(T13*(1-AQ13)*(1-Settings!$F$17))),"") | O13: =IFERROR(IF(T13="","",(T13*(1-AR13)*(1-Settings!$G$17)-I13)/(T13*(1-AR13)*(1-Settings!$G$17))),"") | P13: =IFERROR(IF(T13="","",(T13*(1-AS13)*(1-Settings!$H$17)-I13)/(T13*(1-AS13)*(1-Settings!$H$17))),"") | Q13: =IFERROR(IF(T13="","",(T13*(1-AT13)*(1-Settings!$I$68)*(1-Settings!$I$17)-I13)/(T13*(1-AT13)*(1-Settings!$I$68)*(1-Settings!$I$17))),"") | R13: =IFERROR(IF(OR(I13="",Z13>=1,Settings!$B$17>=1,AN13>=1),"",IF(MOD(ROUND(I13/(1-Z13)/(1-Settings!$B$17)/(1-AN13),0),10)=0,ROUND(I13/(1-Z13)/(1-Settings!$B$17)/(1-AN13),0)-1,IF(MOD(ROUND(I13/(1-Z13)/(1-Settings!$B$17)/(1-AN13),0),10)<=5,FLOOR(ROUND(I13/(1-Z13)/(1-Settings!$B$17)/(1-AN13),0),10)+6,FLOOR(ROUND(I13/(1-Z13)/(1-Settings!$B$17)/(1-AN13),0),10)+9))),"") | S13: 1539 | T13: =IF(S13<>"", IF(MOD(S13,10)=0,S13-1,IF(MOD(S13,10)<=5,FLOOR(S13,10)+6,FLOOR(S13,10)+9)), R13) | U13: Основний | X13: =IFERROR(IF(OR(V13="",W13="",T13=""),"", IF(T13>W13,"Дорогий",IF(T13<V13,"Дешевий","У ринку"))),"") | Z13: =CHOOSE(MATCH(IF($U13="","Основний",$U13),{"Трафіковий","Основний","Маржинальний","Сезонний","Стратегічний"},0),0.16,0.19,0.24,0.23,0.28) | AA13: =CHOOSE(MATCH(IF($U13="","Основний",$U13),{"Трафіковий","Основний","Маржинальний","Сезонний","Стратегічний"},0),0.18,0.21,0.26,0.25,0.3) | AB13: =CHOOSE(MATCH(IF($U13="","Основний",$U13),{"Трафіковий","Основний","Маржинальний","Сезонний","Стратегічний"},0),0.19,0.22,0.28,0.26,0.32) | AC13: =CHOOSE(MATCH(IF($U13="","Основний",$U13),{"Трафіковий","Основний","Маржинальний","Сезонний","Стратегічний"},0),0.17,0.2,0.25,0.24,0.28) | AD13: =CHOOSE(MATCH(IF($U13="","Основний",$U13),{"Трафіковий","Основний","Маржинальний","Сезонний","Стратегічний"},0),0.18,0.21,0.26,0.25,0.3) | AE13: =CHOOSE(MATCH(IF($U13="","Основний",$U13),{"Трафіковий","Основний","Маржинальний","Сезонний","Стратегічний"},0),0.18,0.2,0.28,0.27,0.32) | AF13: =CHOOSE(MATCH(IF($U13="","Основний",$U13),{"Трафіковий","Основний","Маржинальний","Сезонний","Стратегічний"},0),0.15,0.175,0.22,0.21,0.25) | AG13: =CHOOSE(MATCH(IF($U13="","Основний",$U13),{"Трафіковий","Основний","Маржинальний","Сезонний","Стратегічний"},0),0.13,0.16,0.21,0.2,0.25) | AH13: =CHOOSE(MATCH(IF($U13="","Основний",$U13),{"Трафіковий","Основний","Маржинальний","Сезонний","Стратегічний"},0),0.15,0.18,0.23,0.22,0.27) | AI13: =CHOOSE(MATCH(IF($U13="","Основний",$U13),{"Трафіковий","Основний","Маржинальний","Сезонний","Стратегічний"},0),0.16,0.19,0.25,0.23,0.29) | AJ13: =CHOOSE(MATCH(IF($U13="","Основний",$U13),{"Трафіковий","Основний","Маржинальний","Сезонний","Стратегічний"},0),0.14,0.17,0.22,0.21,0.25) | AK13: =CHOOSE(MATCH(IF($U13="","Основний",$U13),{"Трафіковий","Основний","Маржинальний","Сезонний","Стратегічний"},0),0.15,0.18,0.23,0.22,0.27) | AL13: =CHOOSE(MATCH(IF($U13="","Основний",$U13),{"Трафіковий","Основний","Маржинальний","Сезонний","Стратегічний"},0),0.15,0.17,0.25,0.24,0.29) | AM13: =CHOOSE(MATCH(IF($U13="","Основний",$U13),{"Трафіковий","Основний","Маржинальний","Сезонний","Стратегічний"},0),0.12,0.145,0.19,0.18,0.22) | AN13: =CHOOSE(MATCH(IF($U13="","Основний",$U13),{"Трафіковий","Основний","Маржинальний","Сезонний","Стратегічний"},0),Settings!$B$78,Settings!$B$80,Settings!$B$82,Settings!$B$84,Settings!$B$86) | AO13: =CHOOSE(MATCH(IF($U13="","Основний",$U13),{"Трафіковий","Основний","Маржинальний","Сезонний","Стратегічний"},0),Settings!$C$78,Settings!$C$80,Settings!$C$82,Settings!$C$84,Settings!$C$86) | AP13: =CHOOSE(MATCH(IF($U13="","Основний",$U13),{"Трафіковий","Основний","Маржинальний","Сезонний","Стратегічний"},0),Settings!$D$78,Settings!$D$80,Settings!$D$82,Settings!$D$84,Settings!$D$86) | AQ13: =CHOOSE(MATCH(IF($U13="","Основний",$U13),{"Трафіковий","Основний","Маржинальний","Сезонний","Стратегічний"},0),Settings!$F$78,Settings!$F$80,Settings!$F$82,Settings!$F$84,Settings!$F$86) | AR13: =CHOOSE(MATCH(IF($U13="","Основний",$U13),{"Трафіковий","Основний","Маржинальний","Сезонний","Стратегічний"},0),Settings!$G$78,Settings!$G$80,Settings!$G$82,Settings!$G$84,Settings!$G$86) | AS13: =CHOOSE(MATCH(IF($U13="","Основний",$U13),{"Трафіковий","Основний","Маржинальний","Сезонний","Стратегічний"},0),Settings!$H$78,Settings!$H$80,Settings!$H$82,Settings!$H$84,Settings!$H$86) | AT13: =CHOOSE(MATCH(IF($U13="","Основний",$U13),{"Трафіковий","Основний","Маржинальний","Сезонний","Стратегічний"},0),Settings!$I$78,Settings!$I$80,Settings!$I$82,Settings!$I$84,Settings!$I$86) | AV13: 1.35
